Workbook

Sheet Atletas
A1: Nome do Jogador | B1: Clube Atual | C1: Clube Real | D1: Nacionalidade | E1: Idade | F1: Data de Nascimento | G1: Início do contrato | H1: Final do contrato | I1: Salário | J1: Empresário | K1: Posição | L1: Lesões no ano | M1: Dias sem jogar por lesão | N1: Valor de Mercado Nacional | O1: Valor de Mercado Internacional | P1: Pé Dominante | Q1: Ganho por Fornecedor | R1: Fornecedor | S1: Altura | T1: Data de hoje | U1: Dias para o final de contrato | V1: Contrato | W1: Gasto semestral | X1: Gasto anual (Com 13 salario)
A2: Mycael Pontes Moreira | B2: Athletico Paranaense | C2: Athletico Paranaense | D2: Brasil | E2: =DATEDIF(F2,TODAY(),"Y") -> 22 | F2: 38058 | G2: 44927 | H2: 46477 | I2: 185000 | J2: Master Talents | K2: Goleiro | L2: 0 | M2: 0 | N2: 3000000 | O2: =N2*3.5 -> 10500000 | P2: Esquerdo | Q2: =IF(E2>30,100000,IF(E2>24,120000,IF(E2>16,160000))) -> 160000 | R2: Nike | S2: 1.91 | T2: =TODAY() -> 46296 | U2: =_xlfn.DAYS(H2,T2) -> 181 | V2: =IF(U2<180, "Pre contrato","Com Contrato em vigor") -> Com Contrato em vigor | W2: =I2*6 -> 1110000 | X2: =I2*13 -> 2405000
A3: Leonardo Matias Baiersdorf Linck | B3: Athletico Paranaense | C3: Athletico Paranaense | D3: Brasil | E3: =DATEDIF(F3,TODAY(),"Y") -> 25 | F3: 36953 | G3: 44927 | H3: 46387 | I3: 116000 | J3: R13 Fussball | K3: Goleiro | L3: 0 | M3: 0 | N3: 1000000 | O3: =N3*3.5 -> 3500000 | P3: Direito | Q3: =IF(E3>30,100000,IF(E3>24,120000,IF(E3>16,160000))) -> 120000 | R3: Nike | S3: 1.94 | T3: =TODAY() -> 46296 | U3: =_xlfn.DAYS(H3,T3) -> 91 | V3: =IF(U3<180, "Pre contrato","Com Contrato em vigor") -> Pre contrato | W3: =I3*6 -> 696000 | X3: =I3*13 -> 1508000
A4: Matheus Soares Rocha | B4: Athletico Paranaense | C4: Athletico Paranaense | D4: Brasil | E4: =DATEDIF(F4,TODAY(),"Y") -> 21 | F4: 38362 | G4: 45478 | H4: 45657 | I4: 73000 | J4: F3 Sports | K4: Goleiro | L4: 0 | M4: 0 | N4: 90000 | O4: =N4*3.5 -> 315000 | P4: Esquerdo | Q4: =IF(E4>30,100000,IF(E4>24,120000,IF(E4>16,160000))) -> 160000 | R4: Adidas | S4: 1.9 | T4: =TODAY() -> 46296 | U4: =_xlfn.DAYS(H4,T4) -> -639 | V4: =IF(U4<180, "Pre contrato","Com Contrato em vigor") -> Pre contrato | W4: =I4*6 -> 438000 | X4: =I4*13 -> 949000
A5: Kaique Rocha Lima | B5: Athletico Paranaense | C5: Athletico Paranaense | D5: Brasil | E5: =DATEDIF(F5,TODAY(),"Y") -> 25 | F5: 36950 | G5: 44946 | H5: 46387 | I5: 120000 | J5: BBM Sports | K5: Zagueiro | L5: 0 | M5: 0 | N5: 1000000 | O5: =N5*3.5 -> 3500000 | P5: Direito | Q5: =IF(E5>30,100000,IF(E5>24,120000,IF(E5>16,160000))) -> 120000 | R5: Puma | S5: 1.95 | T5: =TODAY() -> 46296 | U5: =_xlfn.DAYS(H5,T5) -> 91 | V5: =IF(U5<180, "Pre contrato","Com Contrato em vigor") -> Pre contrato | W5: =I5*6 -> 720000 | X5: =I5*13 -> 1560000
A6: Mateo Gamarra González | B6: Athletico Paranaense | C6: Athletico Paranaense | D6: Paraguai | E6: =DATEDIF(F6,TODAY(),"Y") -> 25 | F6: 36819 | G6: 45292 | H6: 46752 | I6: 220000 | J6: EagleEye | K6: Zagueiro | L6: 1 | M6: 12 | N6: 3000000 | O6: =N6*3.5 -> 10500000 | P6: Esquerdo | Q6: =IF(E6>30,100000,IF(E6>24,120000,IF(E6>16,160000))) -> 120000 | R6: Adidas | S6: 1.83 | T6: =TODAY() -> 46296 | U6: =_xlfn.DAYS(H6,T6) -> 456 | V6: =IF(U6<180, "Pre contrato","Com Contrato em vigor") -> Com Contrato em vigor | W6: =I6*6 -> 1320000 | X6: =I6*13 -> 2860000
A7: Luan Patrick Wiedthauper | B7: Athletico Paranaense | C7: Athletico Paranaense | D7: Brasil | E7: =DATEDIF(F7,TODAY(),"Y") -> 24 | F7: 37276 | G7: 44587 | H7: 45657 | I7: 140000 | J7: UJ Football Talent | K7: Zagueiro | L7: 1 | M7: 90 | N7: 780000 | O7: =N7*3.5 -> 2730000 | P7: Direito | Q7: =IF(E7>30,100000,IF(E7>24,120000,IF(E7>16,160000))) -> 160000 | R7: Nike | S7: 1.9 | T7: =TODAY() -> 46296 | U7: =_xlfn.DAYS(H7,T7) -> -639 | V7: =IF(U7<180, "Pre contrato","Com Contrato em vigor") -> Pre contrato | W7: =I7*6 -> 840000 | X7: =I7*13 -> 1820000
A8: Lucas Belezi Barbosa | B8: Athletico Paranaense | C8: Athletico Paranaense | D8: Brasil | E8: =DATEDIF(F8,TODAY(),"Y") -> 23 | F8: 37749 | G8: 45292 | H8: 46022 | I8: 150000 | J8: FJB Sports | K8: Zagueiro | L8: 2 | M8: 53 | N8: 1240000 | O8: =N8*3.5 -> 4340000 | P8: Direito | Q8: =IF(E8>30,100000,IF(E8>24,120000,IF(E8>16,160000))) -> 160000 | R8: Adidas | S8: 1.86 | T8: =TODAY() -> 46296 | U8: =_xlfn.DAYS(H8,T8) -> -274 | V8: =IF(U8<180, "Pre contrato","Com Contrato em vigor") -> Pre contrato | W8: =I8*6 -> 900000 | X8: =I8*13 -> 1950000
A9: Thiago Heleno Henrique Ferreira | B9: Athletico Paranaense | C9: Athletico Paranaense | D9: Brasil | E9: =DATEDIF(F9,TODAY(),"Y") -> 38 | F9: 32403 | G9: 42755 | H9: 46022 | I9: 450000 | J9: More than Sport GmbH | K9: Zagueiro | L9: 3 | M9: 41 | N9: 650000 | O9: =N9*3.5 -> 2275000 | P9: Esquerdo | Q9: =IF(E9>30,100000,IF(E9>24,120000,IF(E9>16,160000))) -> 100000 | R9: Nike | S9: 1.87 | T9: =TODAY() -> 46296 | U9: =_xlfn.DAYS(H9,T9) -> -274 | V9: =IF(U9<180, "Pre contrato","Com Contrato em vigor") -> Pre contrato | W9: =I9*6 -> 2700000 | X9: =I9*13 -> 5850000
A10: Marcos Victor Ferreira da Silva | B10: Athletico Paranaense | C10: EC Bahia | D10: Brasil | E10: =DATEDIF(F10,TODAY(),"Y") -> 24 | F10: 37251 | G10: 45538 | H10: 46752 | I10: 160000 | J10: LINK SPORTS | K10: Zagueiro | L10: 0 | M10: 0 | N10: 600000 | O10: =N10*3.5 -> 2100000 | P10: Direito | Q10: =IF(E10>30,100000,IF(E10>24,120000,IF(E10>16,160000))) -> 160000 | R10: Puma | S10: 1.84 | T10: =TODAY() -> 46296 | U10: =_xlfn.DAYS(H10,T10) -> 456 | V10: =IF(U10<180, "Pre contrato","Com Contrato em vigor") -> Com Contrato em vigor | W10: =I10*6 -> 960000 | X10: =I10*13 -> 2080000
A11: Lucas Ángel Esquivel | B11: Athletico Paranaense | C11: Athletico Paranaense | D11: Argentina | E11: =DATEDIF(F11,TODAY(),"Y") -> 24 | F11: 37178 | G11: 45110 | H11: 46934 | I11: 310000 | J11: Universal Twenty Two | K11: Lateral Esquerdo | L11: 2 | M11: 21 | N11: 2300000 | O11: =N11*3.5 -> 8050000 | P11: Esquerdo | Q11: =IF(E11>30,100000,IF(E11>24,120000,IF(E11>16,160000))) -> 160000 | R11: Puma | S11: 1.83 | T11: =TODAY() -> 46296 | U11: =_xlfn.DAYS(H11,T11) -> 638 | V11: =IF(U11<180, "Pre contrato","Com Contrato em vigor") -> Com Contrato em vigor | W11: =I11*6 -> 1860000 | X11: =I11*13 -> 4030000
A12: Fernando Augusto Pereira Bueno Júnior | B12: Athletico Paranaense | C12: Athletico Paranaense | D12: Brasil | E12: =DATEDIF(F12,TODAY(),"Y") -> 27 | F12: 36417 | G12: 44942 | H12: 46387 | I12: 230000 | J12: Elenko Sports Ltda | K12: Lateral Esquerdo | L12: 4 | M12: 35 | N12: 867000 | O12: =N12*3.5 -> 3034500 | P12: Esquerdo | Q12: =IF(E12>30,100000,IF(E12>24,120000,IF(E12>16,160000))) -> 120000 | R12: Nike | S12: 1.81 | T12: =TODAY() -> 46296 | U12: =_xlfn.DAYS(H12,T12) -> 91 | V12: =IF(U12<180, "Pre contrato","Com Contrato em vigor") -> Pre contrato | W12: =I12*6 -> 1380000 | X12: =I12*13 -> 2990000
A13: Leonardo Ezequiel Godoy | B13: Athletico Paranaense | C13: Athletico Paranaense | D13: Argentina | E13: =DATEDIF(F13,TODAY(),"Y") -> 31 | F13: 34817 | G13: 45302 | H13: 46752 | I13: 410000 | J13: FC3 Sports | K13: Lateral Direito | L13: 2 | M13: 16 | N13: 4000000 | O13: =N13*3.5 -> 14000000 | P13: Direito | Q13: =IF(E13>30,100000,IF(E13>24,120000,IF(E13>16,160000))) -> 100000 | R13: Mizuno | S13: 1.73 | T13: =TODAY() -> 46296 | U13: =_xlfn.DAYS(H13,T13) -> 456 | V13: =IF(U13<180, "Pre contrato","Com Contrato em vigor") -> Com Contrato em vigor | W13: =I13*6 -> 2460000 | X13: =I13*13 -> 5330000
... A128: Francisco Dyogo Bento Alves | B128: CR Flamengo | C128: CR Flamengo | D128: Brasil | E128: =DATEDIF(F128,TODAY(),"Y") -> 22 | F128: 37995 | G128: 44950 | H128: 46022 | I128: 200000 | J128: LINK SPORTS | K128: Goleiro | L128: 0 | M128: 0 | N128: 1500000 | O128: =N128*3.5 -> 5250000 | P128: Direito | Q128: =IF(E128>30,100000,IF(E128>24,120000,IF(E128>16,160000))) -> 160000 | R128: Nike | S128: 1.8 | T128: =TODAY() -> 46296 | U128: =_xlfn.DAYS(H128,T128) -> -274 | V128: =IF(U128<180, "Pre contrato","Com Contrato em vigor") -> Pre contrato | W128: =I128*6 -> 1200000 | X128: =I128*13 -> 2600000
A129: Leonardo Rech Ortiz | B129: CR Flamengo | C129: CR Flamengo | D129: Brasil | E129: =DATEDIF(F129,TODAY(),"Y") -> 30 | F129: 35067 | G129: 45357 | H129: 47118 | I129: 900000 | J129: Talents Sports | K129: Zagueiro | L129: 0 | M129: 0 | N129: 26000000 | O129: =N129*3.5 -> 91000000 | P129: Direito | Q129: =IF(E129>30,100000,IF(E129>24,120000,IF(E129>16,160000))) -> 120000 | R129: Puma | S129: 1.85 | T129: =TODAY() -> 46296 | U129: =_xlfn.DAYS(H128,T128) -> -274 | V129: =IF(U129<180, "Pre contrato","Com Contrato em vigor") -> Pre contrato | W129: =I129*6 -> 5400000 | X129: =I129*13 -> 11700000
A130: Leonardo Pereira | B130: CR Flamengo | C130: CR Flamengo | D130: Brasil | E130: =DATEDIF(F130,TODAY(),"Y") -> 30 | F130: 35095 | G130: 43861 | H130: 46752 | I130: 600000 | J130: R13 Fussball | K130: Zagueiro | L130: 0 | M130: 0 | N130: 15000000 | O130: =N130*3.5 -> 52500000 | P130: Direito | Q130: =IF(E130>30,100000,IF(E130>24,120000,IF(E130>16,160000))) -> 120000 | R130: Nike | S130: 1.89 | T130: =TODAY() -> 46296 | U130: =_xlfn.DAYS(H130,T130) -> 456 | V130: =IF(U130<180, "Pre contrato","Com Contrato em vigor") -> Com Contrato em vigor | W130: =I130*6 -> 3600000 | X130: =I130*13 -> 7800000
A131: Fabrício Bruno Soares de Faria | B131: CR Flamengo | C131: CR Flamengo | D131: Brasil | E131: =DATEDIF(F131,TODAY(),"Y") -> 30 | F131: 35107 | G131: 44601 | H131: 47118 | I131: 670000 | J131: Sem empresario | K131: Zagueiro | L131: 0 | M131: 0 | N131: 18000000 | O131: =N131*3.5 -> 63000000 | P131: Direito | Q131: =IF(E131>30,100000,IF(E131>24,120000,IF(E131>16,160000))) -> 120000 | R131: Adidas | S131: 1.92 | T131: =TODAY() -> 46296 | U131: =_xlfn.DAYS(H131,T131) -> 822 | V131: =IF(U131<180, "Pre contrato","Com Contrato em vigor") -> Com Contrato em vigor | W131: =I131*6 -> 4020000 | X131: =I131*13 -> 8710000
A132: David Luiz Moreira Marinho | B132: CR Flamengo | C132: CR Flamengo | D132: Brasil | E132: =DATEDIF(F132,TODAY(),"Y") -> 39 | F132: 31889 | G132: 44601 | H132: 47118 | I132: 600000 | J132: Bertolucci Sports | K132: Zagueiro | L132: 1 | M132: 14 | N132: 3000000 | O132: =N132*3.5 -> 10500000 | P132: Direito | Q132: =IF(E132>30,100000,IF(E132>24,120000,IF(E132>16,160000))) -> 100000 | R132: Adidas | S132: 1.89 | T132: =TODAY() -> 46296 | U132: =_xlfn.DAYS(H132,T132) -> 822 | V132: =IF(U132<180, "Pre contrato","Com Contrato em vigor") -> Com Contrato em vigor | W132: =I132*6 -> 3600000 | X132: =I132*13 -> 7800000
A133: Ayrton Lucas Dantas de Medeiros | B133: CR Flamengo | C133: CR Flamengo | D133: Brasil | E133: =DATEDIF(F133,TODAY(),"Y") -> 29 | F133: 35600 | G133: 44927 | H133: 46752 | I133: 500000 | J133: Carlos Leite | K133: Lateral Esquerdo | L133: 0 | M133: 0 | N133: 10000000 | O133: =N133*3.5 -> 35000000 | P133: Esquerdo | Q133: =IF(E133>30,100000,IF(E133>24,120000,IF(E133>16,160000))) -> 120000 | R133: Adidas | S133: 1.8 | T133: =TODAY() -> 46296 | U133: =_xlfn.DAYS(H132,T132) -> 822 | V133: =IF(U133<180, "Pre contrato","Com Contrato em vigor") -> Com Contrato em vigor | W133: =I133*6 -> 3000000 | X133: =I133*13 -> 6500000
A134: Matías Nicolás Viña Susperreguy | B134: CR Flamengo | C134: CR Flamengo | D134: Uruguai | E134: =DATEDIF(F134,TODAY(),"Y") -> 28 | F134: 35743 | G134: 45316 | H134: 47118 | I134: 650000 | J134: Sem empresario | K134: Lateral Esquerdo | L134: 2 | M134: 87 | N134: 14000000 | O134: =N134*3.5 -> 49000000 | P134: Esquerdo | Q134: =IF(E134>30,100000,IF(E134>24,120000,IF(E134>16,160000))) -> 120000 | R134: Adidas | S134: 1.75 | T134: =TODAY() -> 46296 | U134: =_xlfn.DAYS(H134,T134) -> 822 | V134: =IF(U134<180, "Pre contrato","Com Contrato em vigor") -> Com Contrato em vigor | W134: =I134*6 -> 3900000 | X134: =I134*13 -> 8450000
A135: Alex Sandro Lobo Silva | B135: CR Flamengo | C135: CR Flamengo | D135: Brasil | E135: =DATEDIF(F135,TODAY(),"Y") -> 35 | F135: 33264 | G135: 45530 | H135: 46387 | I135: 1500000 | J135: Sem empresario | K135: Lateral Esquerdo | L135: 0 | M135: 0 | N135: 10000000 | O135: =N135*3.5 -> 35000000 | P135: Esquerdo | Q135: =IF(E135>30,100000,IF(E135>24,120000,IF(E135>16,160000))) -> 100000 | R135: Puma | S135: 1.8 | T135: =TODAY() -> 46296 | U135: =_xlfn.DAYS(H135,T135) -> 91 | V135: =IF(U135<180, "Pre contrato","Com Contrato em vigor") -> Pre contrato | W135: =I135*6 -> 9000000 | X135: =I135*13 -> 19500000
A136: Guillermo Varela Olivera | B136: CR Flamengo | C136: CR Flamengo | D136: Uruguai | E136: =DATEDIF(F136,TODAY(),"Y") -> 33 | F136: 34052 | G136: 44938 | H136: 46022 | I136: 600000 | J136: Rickman Sports | K136: Lateral Direito | L136: 0 | M136: 0 | N136: 16000000 | O136: =N136*3.5 -> 56000000 | P136: Direito | Q136: =IF(E136>30,100000,IF(E136>24,120000,IF(E136>16,160000))) -> 100000 | R136: Nike | S136: 1.73 | T136: =TODAY() -> 46296 | U136: =_xlfn.DAYS(H136,T136) -> -274 | V136: =IF(U136<180, "Pre contrato","Com Contrato em vigor") -> Pre contrato | W136: =I136*6 -> 3600000 | X136: =I136*13 -> 7800000
A137: Wesley Vinícius França Lima | B137: CR Flamengo | C137: CR Flamengo | D137: Brasil | E137: =DATEDIF(F137,TODAY(),"Y") -> 23 | F137: 37870 | G137: 44927 | H137: 47118 | I137: 400000 | J137: MCL Sports | K137: Lateral Direito | L137: 0 | M137: 0 | N137: 25000000 | O137: =N137*3.5 -> 87500000 | P137: Direito | Q137: =IF(E137>30,100000,IF(E137>24,120000,IF(E137>16,160000))) -> 160000 | R137: Nike | S137: 1.78 | T137: =TODAY() -> 46296 | U137: =_xlfn.DAYS(H136,T136) -> -274 | V137: =IF(U137<180, "Pre contrato","Com Contrato em vigor") -> Pre contrato | W137: =I137*6 -> 2400000 | X137: =I137*13 -> 5200000
A138: Allan Rodrigues de Souza | B138: CR Flamengo | C138: CR Flamengo | D138: Brasil | E138: =DATEDIF(F138,TODAY(),"Y") -> 29 | F138: 35492 | G138: 45108 | H138: 46752 | I138: 560000 | J138: Bertolucci Sports | K138: Volante | L138: 1 | M138: 60 | N138: 7500000 | O138: =N138*3.5 -> 26250000 | P138: Direito | Q138: =IF(E138>30,100000,IF(E138>24,120000,IF(E138>16,160000))) -> 120000 | R138: Nike | S138: 1.72 | T138: =TODAY() -> 46296 | U138: =_xlfn.DAYS(H138,T138) -> 456 | V138: =IF(U138<180, "Pre contrato","Com Contrato em vigor") -> Com Contrato em vigor | W138: =I138*6 -> 3360000 | X138: =I138*13 -> 7280000
A139: Erick Antonio Pulgar Farfán | B139: CR Flamengo | C139: CR Flamengo | D139: Chile | E139: =DATEDIF(F139,TODAY(),"Y") -> 32 | F139: 34349 | G139: 44771 | H139: 46022 | I139: 550000 | J139: Vibra Futbol | K139: Volante | L139: 0 | M139: 0 | N139: 17000000 | O139: =N139*3.5 -> 59500000 | P139: Direito | Q139: =IF(E139>30,100000,IF(E139>24,120000,IF(E139>16,160000))) -> 100000 | R139: Nike | S139: 1.87 | T139: =TODAY() -> 46296 | U139: =_xlfn.DAYS(H139,T139) -> -274 | V139: =IF(U139<180, "Pre contrato","Com Contrato em vigor") -> Pre contrato | W139: =I139*6 -> 3300000 | X139: =I139*13 -> 7150000
A140: Gerson Santos da Silva | B140: CR Flamengo | C140: CR Flamengo | D140: Brasil | E140: =DATEDIF(F140,TODAY(),"Y") -> 29 | F140: 35570 | G140: 44927 | H140: 46752 | I140: 1200000 | J140: Carlos Leite | K140: Meio Campo | L140: 0 | M140: 0 | N140: 24000000 | O140: =N140*3.5 -> 84000000 | P140: Esquerdo | Q140: =IF(E140>30,100000,IF(E140>24,120000,IF(E140>16,160000))) -> 120000 | R140: Nike | S140: 1.84 | T140: =TODAY() -> 46296 | U140: =_xlfn.DAYS(H140,T140) -> 456 | V140: =IF(U140<180, "Pre contrato","Com Contrato em vigor") -> Com Contrato em vigor | W140: =I140*6 -> 7200000 | X140: =I140*13 -> 15600000
A141: Diego Nicolás de la Cruz Arcosa | B141: CR Flamengo | C141: CR Flamengo | D141: Uruguai | E141: =DATEDIF(F141,TODAY(),"Y") -> 29 | F141: 35582 | G141: 45292 | H141: 46934 | I141: 1200000 | J141: Paco Casal | K141: Meio Campo | L141: 2 | M141: 21 | N141: 22000000 | O141: =N141*3.5 -> 77000000 | P141: Esquerdo | Q141: =IF(E141>30,100000,IF(E141>24,120000,IF(E141>16,160000))) -> 120000 | R141: Nike | S141: 1.67 | T141: =TODAY() -> 46296 | U141: =_xlfn.DAYS(H140,T140) -> 456 | V141: =IF(U141<180, "Pre contrato","Com Contrato em vigor") -> Com Contrato em vigor | W141: =I141*6 -> 7200000 | X141: =I141*13 -> 15600000
A142: Carlos Jonás Alcaraz | B142: CR Flamengo | C142: CR Flamengo | D142: Argentina | E142: =DATEDIF(F142,TODAY(),"Y") -> 23 | F142: 37590 | G142: 45532 | H142: 47299 | I142: 1000000 | J142: Rol Sports Management | K142: Meio Campo | L142: 1 | M142: 10 | N142: 30000000 | O142: =N142*3.5 -> 105000000 | P142: Direito | Q142: =IF(E142>30,100000,IF(E142>24,120000,IF(E142>16,160000))) -> 160000 | R142: Nike | S142: 1.83 | T142: =TODAY() -> 46296 | U142: =_xlfn.DAYS(H142,T142) -> 1003 | V142: =IF(U142<180, "Pre contrato","Com Contrato em vigor") -> Com Contrato em vigor | W142: =I142*6 -> 6000000 | X142: =I142*13 -> 13000000
A143: Giorgian Daniel de Arrascaeta Benedetti | B143: CR Flamengo | C143: CR Flamengo | D143: Uruguai | E143: =DATEDIF(F143,TODAY(),"Y") -> 32 | F143: 34486 | G143: 43477 | H143: 46387 | I143: 1600000 | J143: Daniel Fonseca | K143: Meio Campo | L143: 1 | M143: 50 | N143: 13000000 | O143: =N143*3.5 -> 45500000 | P143: Direito | Q143: =IF(E143>30,100000,IF(E143>24,120000,IF(E143>16,160000))) -> 100000 | R143: Nike | S143: 1.74 | T143: =TODAY() -> 46296 | U143: =_xlfn.DAYS(H143,T143) -> 91 | V143: =IF(U143<180, "Pre contrato","Com Contrato em vigor") -> Pre contrato | W143: =I143*6 -> 9600000 | X143: =I143*13 -> 20800000
A144: Lorran Lucas Pereira de Sousa | B144: CR Flamengo | C144: CR Flamengo | D144: Brasil | E144: =DATEDIF(F144,TODAY(),"Y") -> 20 | F144: 38902 | G144: 45292 | H144: 47483 | I144: 150000 | J144: Roc Nation Sports | K144: Meio Campo | L144: 0 | M144: 0 | N144: 14000000 | O144: =N144*3.5 -> 49000000 | P144: Direito | Q144: =IF(E144>30,100000,IF(E144>24,120000,IF(E144>16,160000))) -> 160000 | R144: Nike | S144: 1.8 | T144: =TODAY() -> 46296 | U144: =_xlfn.DAYS(H144,T144) -> 1187 | V144: =IF(U144<180, "Pre contrato","Com Contrato em vigor") -> Com Contrato em vigor | W144: =I144*6 -> 900000 | X144: =I144*13 -> 1950000
A145: Everton Sousa Soares | B145: CR Flamengo | C145: CR Flamengo | D145: Brasil | E145: =DATEDIF(F145,TODAY(),"Y") -> 30 | F145: 35146 | G145: 44760 | H145: 46203 | I145: 1500000 | J145: Bertolucci Sports | K145: Atacante | L145: 1 | M145: 45 | N145: 16000000 | O145: =N145*3.5 -> 56000000 | P145: Direito | Q145: =IF(E145>30,100000,IF(E145>24,120000,IF(E145>16,160000))) -> 120000 | R145: Nike | S145: 1.74 | T145: =TODAY() -> 46296 | U145: =_xlfn.DAYS(H144,T144) -> 1187 | V145: =IF(U145<180, "Pre contrato","Com Contrato em vigor") -> Com Contrato em vigor | W145: =I145*6 -> 9000000 | X145: =I145*13 -> 19500000
A146: Michael Richard Delgado de Oliveira | B146: CR Flamengo | C146: CR Flamengo | D146: Brasil | E146: =DATEDIF(F146,TODAY(),"Y") -> 30 | F146: 35136 | G146: 45526 | H146: 47118 | I146: 1600000 | J146: Dut's Mkt | K146: Atacante | L146: 0 | M146: 0 | N146: 18000000 | O146: =N146*3.5 -> 63000000 | P146: Direito | Q146: =IF(E146>30,100000,IF(E146>24,120000,IF(E146>16,160000))) -> 120000 | R146: Nike | S146: 1.66 | T146: =TODAY() -> 46296 | U146: =_xlfn.DAYS(H146,T146) -> 822 | V146: =IF(U146<180, "Pre contrato","Com Contrato em vigor") -> Com Contrato em vigor | W146: =I146*6 -> 9600000 | X146: =I146*13 -> 20800000
A147: Bruno Henrique Pinto | B147: CR Flamengo | C147: CR Flamengo | D147: Brasil | E147: =DATEDIF(F147,TODAY(),"Y") -> 35 | F147: 33237 | G147: 43488 | H147: 46387 | I147: 2000000 | J147: Sem empresario | K147: Atacante | L147: 2 | M147: 34 | N147: 10000000 | O147: =N147*3.5 -> 35000000 | P147: Direito | Q147: =IF(E147>30,100000,IF(E147>24,120000,IF(E147>16,160000))) -> 100000 | R147: Nike | S147: 1.84 | T147: =TODAY() -> 46296 | U147: =_xlfn.DAYS(H147,T147) -> 91 | V147: =IF(U147<180, "Pre contrato","Com Contrato em vigor") -> Pre contrato | W147: =I147*6 -> 12000000 | X147: =I147*13 -> 26000000
A148: Luiz de Araújo Guimarães Neto | B148: CR Flamengo | C148: CR Flamengo | D148: Brasil | E148: =DATEDIF(F148,TODAY(),"Y") -> 30 | F148: 35218 | G148: 45108 | H148: 46752 | I148: 1300000 | J148: Trust Football | K148: Atacante | L148: 1 | M148: 40 | N148: 12000000 | O148: =N148*3.5 -> 42000000 | P148: Esquerdo | Q148: =IF(E148>30,100000,IF(E148>24,120000,IF(E148>16,160000))) -> 120000 | R148: Adidas | S148: 1.75 | T148: =TODAY() -> 46296 | U148: =_xlfn.DAYS(H148,T148) -> 456 | V148: =IF(U148<180, "Pre contrato","Com Contrato em vigor") -> Com Contrato em vigor | W148: =I148*6 -> 7800000 | X148: =I148*13 -> 16900000
A149: Gonzalo Jordy Plata Jiménez | B149: CR Flamengo | C149: CR Flamengo | D149: Equador | E149: =DATEDIF(F149,TODAY(),"Y") -> 25 | F149: 36831 | G149: 45534 | H149: 47299 | I149: 450000 | J149: AS1 | K149: Atacante | L149: 0 | M149: 0 | N149: 7500000 | O149: =N149*3.5 -> 26250000 | P149: Esquerdo | Q149: =IF(E149>30,100000,IF(E149>24,120000,IF(E149>16,160000))) -> 120000 | R149: Adidas | S149: 1.78 | T149: =TODAY() -> 46296 | U149: =_xlfn.DAYS(H148,T148) -> 456 | V149: =IF(U149<180, "Pre contrato","Com Contrato em vigor") -> Com Contrato em vigor | W149: =I149*6 -> 2700000 | X149: =I149*13 -> 5850000
A150: Gabriel Barbosa Almeida | B150: CR Flamengo | C150: CR Flamengo | D150: Brasil | E150: =DATEDIF(F150,TODAY(),"Y") -> 30 | F150: 35307 | G150: 45658 | H150: 47118 | I150: 1800000 | J150: 4ComM | K150: Atacante | L150: 0 | M150: 0 | N150: 10000000 | O150: =N150*3.5 -> 35000000 | P150: Esquerdo | Q150: =IF(E150>30,100000,IF(E150>24,120000,IF(E150>16,160000))) -> 120000 | R150: Mizuno | S150: 1.78 | T150: =TODAY() -> 46296 | U150: =_xlfn.DAYS(H150,T150) -> 822 | V150: =IF(U150<180, "Pre contrato","Com Contrato em vigor") -> Com Contrato em vigor | W150: =I150*6 -> 10800000 | X150: =I150*13 -> 23400000
A151: Pedro Guilherme Abreu dos Santos | B151: CR Flamengo | C151: CR Flamengo | D151: Brasil | E151: =DATEDIF(F151,TODAY(),"Y") -> 29 | F151: 35601 | G151: 44197 | H151: 46752 | I151: 1350000 | J151: Bertolucci Sports | K151: Atacante | L151: 1 | M151: 90 | N151: 15000000 | O151: =N151*3.5 -> 52500000 | P151: Direito | Q151: =IF(E151>30,100000,IF(E151>24,120000,IF(E151>16,160000))) -> 120000 | R151: Adidas | S151: 1.85 | T151: =TODAY() -> 46296 | U151: =_xlfn.DAYS(H151,T151) -> 456 | V151: =IF(U151<180, "Pre contrato","Com Contrato em vigor") -> Com Contrato em vigor | W151: =I151*6 -> 8100000 | X151: =I151*13 -> 17550000
A152: Carlos Moises de Lima | B152: CR Flamengo | C152: CR Flamengo | D152: Brasil | E152: =DATEDIF(F152,TODAY(),"Y") -> 29 | F152: 35473 | G152: 45390 | H152: 46387 | I152: 200000 | J152: JBSports | K152: Atacante | L152: 0 | M152: 0 | N152: 3000000 | O152: =N152*3.5 -> 10500000 | P152: Esquerdo | Q152: =IF(E152>30,100000,IF(E152>24,120000,IF(E152>16,160000))) -> 120000 | R152: Nike | S152: 1.95 | T152: =TODAY() -> 46296 | U152: =_xlfn.DAYS(H152,T152) -> 91 | V152: =IF(U152<180, "Pre contrato","Com Contrato em vigor") -> Pre contrato | W152: =I152*6 -> 1200000 | X152: =I152*13 -> 2600000
A153: Léonardo César Jardim | B153: CR Vasco da Gama | C153: CR Vasco da Gama | D153: Brasil | E153: =DATEDIF(F153,TODAY(),"Y") -> 31 | F153: 34778 | G153: 44953 | H153: 46022 | I153: 230000 | J153: Talents Sports | K153: Goleiro | L153: 0 | M153: 0 | N153: 21000000 | O153: =N153*3.5 -> 73500000 | P153: Direito | Q153: =IF(E153>30,100000,IF(E153>24,120000,IF(E153>16,160000))) -> 100000 | R153: Nike | S153: 1.88 | T153: =TODAY() -> 46296 | U153: =_xlfn.DAYS(H152,T152) -> 91 | V153: =IF(U153<180, "Pre contrato","Com Contrato em vigor") -> Pre contrato | W153: =I153*6 -> 1380000 | X153: =I153*13 -> 2990000
A154: Keiller da Silva Nunes | B154: CR Vasco da Gama | C154: CR Vasco da Gama | D154: Brasil | E154: =DATEDIF(F154,TODAY(),"Y") -> 29 | F154: 35367 | G154: 45390 | H154: 46387 | I154: 100000 | J154: P&P Sport Management S.A.M. | K154: Goleiro | L154: 0 | M154: 0 | N154: 3000000 | O154: =N154*3.5 -> 10500000 | P154: Direito | Q154: =IF(E154>30,100000,IF(E154>24,120000,IF(E154>16,160000))) -> 120000 | R154: Nike | S154: 1.93 | T154: =TODAY() -> 46296 | U154: =_xlfn.DAYS(H154,T154) -> 91 | V154: =IF(U154<180, "Pre contrato","Com Contrato em vigor") -> Pre contrato | W154: =I154*6 -> 600000 | X154: =I154*13 -> 1300000
...

Sheet Clube
A1: Clube | B1: Estado | C1: Pay Per View | D1: Receita de TV | E1: Salario dos jogadores mensal | F1: Salario dos jogadores anual | G1: Torcida no estado | H1: Estadio mandante | I1: Socio torcedor | J1: Capacidade do estadio | K1: Preco medio dos ingressos do estadio | L1: media de publico por jogo no estadio | M1: Média de renda por jogo | N1: Renda total no estadio | O1: Projeção de Venda de Atletas
A2: Athletico Paranaense | B2: PA | C2: 0 | D2: 10 | E2: =SUMIF(Atletas!B:B, A2, Atletas!I:I) -> 11148000 | F2: =SUMIF(Atletas!B:B, A2, Atletas!X:X) -> 144924000 | G2: 1.5 | H2: Ligga Arena | I2: 40000 | J2: 42372 | K2: 35.63 | L2: 28310 | M2: 1007365.4 | N2: 34250425 | O2: =100 * 1000000 -> 100000000
A3: Atlético Goianiense | B3: GO | C3: 0 | D3: 10 | E3: =SUMIF(Atletas!B:B, A3, Atletas!I:I) -> 1001267 | F3: =SUMIF(Atletas!B:B, A3, Atletas!X:X) -> 13016471 | G3: 0.2 | H3: Estádio Antonio Accioly | I3: 7294 | J3: 13000 | K3: 55.25 | L3: 6462 | M3: 357038.5 | N3: 10711155 | O3: =5 * 1000000 -> 5000000
A4: Criciúma EC | B4: SC | C4: 0 | D4: 10 | E4: =SUMIF(Atletas!B:B, A4, Atletas!I:I) -> 2056000 | F4: =SUMIF(Atletas!B:B, A4, Atletas!X:X) -> 26728000 | G4: 0.2 | H4: Estádio Heriberto Hülse | I4: 16000 | J4: 19225 | K4: 38.32 | L4: 12748 | M4: 488511 | N4: 14655330 | O4: =5* 1000000 -> 5000000
A5: Cuiabá EC | B5: MS | C5: 0 | D5: 15 | E5: =SUMIF(Atletas!B:B, A5, Atletas!I:I) -> 4684000 | F5: =SUMIF(Atletas!B:B, A5, Atletas!X:X) -> 60892000 | G5: 0.4 | H5: Arena Pantanal | I5: 3000 | J5: 42968 | K5: 63.38 | L5: 7572 | M5: 267247.06 | N5: 9086400 | O5: =5* 1000000 -> 5000000
A6: EC Juventude | B6: RS | C6: 0 | D6: 10 | E6: =SUMIF(Atletas!B:B, A6, Atletas!I:I) -> 2105000 | F6: =SUMIF(Atletas!B:B, A6, Atletas!X:X) -> 27365000 | G6: 0.2 | H6: Estádio Alfredo Jaconi | I6: 8380 | J6: 23726 | K6: 50.58 | L6: 8654 | M6: 437704.23 | N6: 13131127 | O6: =10 * 1000000 -> 10000000
A7: EC Vitória | B7: BA | C7: 0 | D7: 10 | E7: =SUMIF(Atletas!B:B, A7, Atletas!I:I) -> 5575000 | F7: =SUMIF(Atletas!B:B, A7, Atletas!X:X) -> 72475000 | G7: 3.9 | H7: Estádio Manoel Barradas | I7: 40638 | J7: 30618 | K7: 26.88 | L7: 20391 | M7: 548119.4 | N7: 16443582 | O7: =15* 1000000 -> 15000000
A8: RB Bragantino | B8: SP | C8: 0 | D8: 10 | E8: =SUMIF(Atletas!B:B, A8, Atletas!I:I) -> 13474000 | F8: =SUMIF(Atletas!B:B, A8, Atletas!X:X) -> 175162000 | G8: 0.2 | H8: Estádio Nabi Abi Chedid | I8: 7500 | J8: 15010 | K8: 43.84 | L8: 5987 | M8: 243104.14 | N8: 8508645 | O8: =40* 1000000 -> 40000000
A9: CR Flamengo | B9: RJ | C9: 177 | D9: 25 | E9: =SUMIF(Atletas!B:B, A9, Atletas!I:I) -> 24280000 | F9: =SUMIF(Atletas!B:B, A9, Atletas!X:X) -> 315640000 | G9: 43.2 | H9: Estádio Jornalista Mário Filho | I9: 77577 | J9: 78838 | K9: 68.06 | L9: 51644 | M9: 3514821.7 | N9: 130048403 | O9: =103 * 1000000 -> 103000000
A10: SC Corinthians | B10: SP | C10: 118 | D10: 19 | E10: =SUMIF(Atletas!B:B, A10, Atletas!I:I) -> 20170000 | F10: =SUMIF(Atletas!B:B, A10, Atletas!X:X) -> 262210000 | G10: 31.1 | H10: Neo Química Arena | I10: 43000 | J10: 49205 | K10: 57.32 | L10: 42693 | M10: 2446942.5 | N10: 85642986 | O10: =180 * 1000000 -> 180000000
A11: Grêmio FBPA | B11: RS | C11: 57 | D11: 36 | E11: =SUMIF(Atletas!B:B, A11, Atletas!I:I) -> 15400000 | F11: =SUMIF(Atletas!B:B, A11, Atletas!X:X) -> 200200000 | G11: 9.9 | H11: Arena do Grêmio | I11: 98153 | J11: 60540 | K11: 61.38 | L11: 22002 | M11: 1350509.5 | N11: 45917324 | O11: =90 * 1000000 -> 90000000
A12: SE Palmeiras | B12: SP | C12: 50 | D12: 33 | E12: =SUMIF(Atletas!B:B, A12, Atletas!I:I) -> 15880000 | F12: =SUMIF(Atletas!B:B, A12, Atletas!X:X) -> 206440000 | G12: 16.3 | H12: Allianz Parque | I12: 197327 | J12: 43713 | K12: 83.91 | L12: 30490 | M12: 2558529.9 | N12: 86990017 | O12: =295.1 * 1000000 -> 295100000
A13: São Paulo FC | B13: SP | C13: 28 | D13: 31 | E13: =SUMIF(Atletas!B:B, A13, Atletas!I:I) -> 13316000 | F13: =SUMIF(Atletas!B:B, A13, Atletas!X:X) -> 173108000 | G13: 15.6 | H13: MorumBIS | I13: 57106 | J13: 66795 | K13: 65.49 | L13: 44088 | M13: 2887163.8 | N13: 98163569 | O13: =174.1* 1000000 -> 174100000
A14: CR Vasco da Gama | B14: RJ | C14: 21 | D14: 29 | E14: =SUMIF(Atletas!B:B, A14, Atletas!I:I) -> 11863000 | F14: =SUMIF(Atletas!B:B, A14, Atletas!X:X) -> 154219000 | G14: 14.1 | H14: Estádio São Januário | I14: 62153 | J14: 24584 | K14: 64.91 | L14: 21686 | M14: 1407571.9 | N14: 43634730 | O14: =70* 1000000 -> 70000000
A15: Cruzeiro EC | B15: MG | C15: 18 | D15: 32 | E15: =SUMIF(Atletas!B:B, A15, Atletas!I:I) -> 16052000 | F15: =SUMIF(Atletas!B:B, A15, Atletas!X:X) -> 208676000 | G15: 11.6 | H15: Estádio Governador Magalhães Pinto | I15: 81004 | J15: 61927 | K15: 53.34 | L15: 32890 | M15: 1754414.7 | N15: 52632441 | O15: =80* 1000000 -> 80000000
A16: Atlético Mineiro | B16: MG | C16: 16 | D16: 30 | E16: =SUMIF(Atletas!B:B, A16, Atletas!I:I) -> 12742222 | F16: =SUMIF(Atletas!B:B, A16, Atletas!X:X) -> 165648886 | G16: 8.6 | H16: Arena MRV | I16: 113169 | J16: 46000 | K16: 76.16 | L16: 31962 | M16: 2434137.2 | N16: 80326527 | O16: =60* 1000000 -> 60000000
A17: SC Internacional | B17: RS | C17: 16 | D17: 30 | E17: =SUMIF(Atletas!B:B, A17, Atletas!I:I) -> 17425000 | F17: =SUMIF(Atletas!B:B, A17, Atletas!X:X) -> 226525000 | G17: 6.2 | H17: Estádio Beira-Rio | I17: 107265 | J17: 50848 | K17: 42.82 | L17: 29526 | M17: 1264198.9 | N17: 37925967 | O17: =135* 1000000 -> 135000000
A18: Botafogo FR | B18: RJ | C18: 15 | D18: 33 | E18: =SUMIF(Atletas!B:B, A18, Atletas!I:I) -> 23012000 | F18: =SUMIF(Atletas!B:B, A18, Atletas!X:X) -> 299156000 | G18: 6.2 | H18: Estádio Olímpico Nilton Santos | I18: 80977 | J18: 46931 | K18: 63.08 | L18: 22467 | M18: 1417292 | N18: 52439805 | O18: =100* 1000000 -> 100000000
A19: Fluminense FC | B19: RJ | C19: 11 | D19: 30 | E19: =SUMIF(Atletas!B:B, A19, Atletas!I:I) -> 18175000 | F19: =SUMIF(Atletas!B:B, A19, Atletas!X:X) -> 236275000 | G19: 6 | H19: Estádio Jornalista Mário Filho | I19: 49950 | J19: 78838 | K19: 47.08 | L19: 31699 | M19: 1492477.2 | N19: 50744226 | O19: =80* 1000000 -> 80000000
A20: EC Bahia | B20: BA | C20: 5 | D20: 18 | E20: =SUMIF(Atletas!B:B, A20, Atletas!I:I) -> 15422152 | F20: =SUMIF(Atletas!B:B, A20, Atletas!X:X) -> 200487976 | G20: 6 | H20: Arena Fonte Nova | I20: 75000 | J20: 47364 | K20: 33.88 | L20: 34214 | M20: 1159180.9 | N20: 40571331 | O20: =50* 1000000 -> 50000000
A21: Fortaleza EC | B21: CE | C21: 5 | D21: 13 | E21: =SUMIF(Atletas!B:B, A21, Atletas!I:I) -> 7563000 | F21: =SUMIF(Atletas!B:B, A21, Atletas!X:X) -> 98319000 | G21: 3.4 | H21: Estádio Governador Plácido Castelo | I21: 43860 | J21: 60326 | K21: 21.29 | L21: 30221 | M21: 643266.73 | N21: 23800869 | O21: =40* 1000000 -> 40000000
